2021-04-14 23:17:07,262 - ERROR fialda.py:121 - Failed to screenshot 1 day screenshots/all/daily/
2021-04-14 23:17:07,265 - ERROR fialda.py:122 - [Errno 2] No such file or directory: 'cookies.txt'
2021-04-14 23:18:14,003 - WARNING connectionpool.py:744 - Retrying (Retry(total=2, connect=None, read=None, redirect=None, status=None)) after connection broken by 'NewConnectionError('<urllib3.connection.HTTPConnection object at 0x107606280>: Failed to establish a new connection: [Errno 61] Connection refused')': /session/6701f7e9088bc60ab168473daa188eec/element
2021-04-14 23:18:14,005 - WARNING connectionpool.py:744 - Retrying (Retry(total=1, connect=None, read=None, redirect=None, status=None)) after connection broken by 'NewConnectionError('<urllib3.connection.HTTPConnection object at 0x1076063a0>: Failed to establish a new connection: [Errno 61] Connection refused')': /session/6701f7e9088bc60ab168473daa188eec/element
2021-04-14 23:18:14,006 - WARNING connectionpool.py:744 - Retrying (Retry(total=0, connect=None, read=None, redirect=None, status=None)) after connection broken by 'NewConnectionError('<urllib3.connection.HTTPConnection object at 0x1076064f0>: Failed to establish a new connection: [Errno 61] Connection refused')': /session/6701f7e9088bc60ab168473daa188eec/element
2021-04-14 23:18:14,009 - WARNING connectionpool.py:744 - Retrying (Retry(total=2, connect=None, read=None, redirect=None, status=None)) after connection broken by 'NewConnectionError('<urllib3.connection.HTTPConnection object at 0x107606790>: Failed to establish a new connection: [Errno 61] Connection refused')': /session/6701f7e9088bc60ab168473daa188eec/element
2021-04-14 23:18:14,009 - WARNING connectionpool.py:744 - Retrying (Retry(total=1, connect=None, read=None, redirect=None, status=None)) after connection broken by 'NewConnectionError('<urllib3.connection.HTTPConnection object at 0x10748dc40>: Failed to establish a new connection: [Errno 61] Connection refused')': /session/6701f7e9088bc60ab168473daa188eec/element
2021-04-14 23:18:14,010 - WARNING connectionpool.py:744 - Retrying (Retry(total=0, connect=None, read=None, redirect=None, status=None)) after connection broken by 'NewConnectionError('<urllib3.connection.HTTPConnection object at 0x10748deb0>: Failed to establish a new connection: [Errno 61] Connection refused')': /session/6701f7e9088bc60ab168473daa188eec/element
2021-04-14 23:18:14,012 - WARNING connectionpool.py:744 - Retrying (Retry(total=2, connect=None, read=None, redirect=None, status=None)) after connection broken by 'NewConnectionError('<urllib3.connection.HTTPConnection object at 0x1076065e0>: Failed to establish a new connection: [Errno 61] Connection refused')': /session/6701f7e9088bc60ab168473daa188eec/element
2021-04-14 23:18:14,013 - WARNING connectionpool.py:744 - Retrying (Retry(total=1, connect=None, read=None, redirect=None, status=None)) after connection broken by 'NewConnectionError('<urllib3.connection.HTTPConnection object at 0x1076061c0>: Failed to establish a new connection: [Errno 61] Connection refused')': /session/6701f7e9088bc60ab168473daa188eec/element
2021-04-14 23:18:14,013 - WARNING connectionpool.py:744 - Retrying (Retry(total=0, connect=None, read=None, redirect=None, status=None)) after connection broken by 'NewConnectionError('<urllib3.connection.HTTPConnection object at 0x107606880>: Failed to establish a new connection: [Errno 61] Connection refused')': /session/6701f7e9088bc60ab168473daa188eec/element
2021-04-14 23:18:14,015 - WARNING connectionpool.py:744 - Retrying (Retry(total=2, connect=None, read=None, redirect=None, status=None)) after connection broken by 'NewConnectionError('<urllib3.connection.HTTPConnection object at 0x107606bb0>: Failed to establish a new connection: [Errno 61] Connection refused')': /session/6701f7e9088bc60ab168473daa188eec/element
2021-04-14 23:18:14,015 - WARNING connectionpool.py:744 - Retrying (Retry(total=1, connect=None, read=None, redirect=None, status=None)) after connection broken by 'NewConnectionError('<urllib3.connection.HTTPConnection object at 0x107606d30>: Failed to establish a new connection: [Errno 61] Connection refused')': /session/6701f7e9088bc60ab168473daa188eec/element
2021-04-14 23:18:14,016 - WARNING connectionpool.py:744 - Retrying (Retry(total=0, connect=None, read=None, redirect=None, status=None)) after connection broken by 'NewConnectionError('<urllib3.connection.HTTPConnection object at 0x107606ee0>: Failed to establish a new connection: [Errno 61] Connection refused')': /session/6701f7e9088bc60ab168473daa188eec/element
2021-04-14 23:18:14,018 - WARNING connectionpool.py:744 - Retrying (Retry(total=2, connect=None, read=None, redirect=None, status=None)) after connection broken by 'NewConnectionError('<urllib3.connection.HTTPConnection object at 0x10765d280>: Failed to establish a new connection: [Errno 61] Connection refused')': /session/6701f7e9088bc60ab168473daa188eec/element
2021-04-14 23:18:14,019 - WARNING connectionpool.py:744 - Retrying (Retry(total=1, connect=None, read=None, redirect=None, status=None)) after connection broken by 'NewConnectionError('<urllib3.connection.HTTPConnection object at 0x10765d430>: Failed to establish a new connection: [Errno 61] Connection refused')': /session/6701f7e9088bc60ab168473daa188eec/element
2021-04-14 23:18:14,020 - WARNING connectionpool.py:744 - Retrying (Retry(total=0, connect=None, read=None, redirect=None, status=None)) after connection broken by 'NewConnectionError('<urllib3.connection.HTTPConnection object at 0x10765d5e0>: Failed to establish a new connection: [Errno 61] Connection refused')': /session/6701f7e9088bc60ab168473daa188eec/element
2021-04-14 23:18:14,022 - WARNING connectionpool.py:744 - Retrying (Retry(total=2, connect=None, read=None, redirect=None, status=None)) after connection broken by 'NewConnectionError('<urllib3.connection.HTTPConnection object at 0x10765d8e0>: Failed to establish a new connection: [Errno 61] Connection refused')': /session/6701f7e9088bc60ab168473daa188eec/element
2021-04-14 23:18:14,024 - WARNING connectionpool.py:744 - Retrying (Retry(total=1, connect=None, read=None, redirect=None, status=None)) after connection broken by 'NewConnectionError('<urllib3.connection.HTTPConnection object at 0x10765da60>: Failed to establish a new connection: [Errno 61] Connection refused')': /session/6701f7e9088bc60ab168473daa188eec/element
2021-04-14 23:18:14,026 - WARNING connectionpool.py:744 - Retrying (Retry(total=0, connect=None, read=None, redirect=None, status=None)) after connection broken by 'NewConnectionError('<urllib3.connection.HTTPConnection object at 0x10748de50>: Failed to establish a new connection: [Errno 61] Connection refused')': /session/6701f7e9088bc60ab168473daa188eec/element
2021-04-14 23:18:14,028 - WARNING connectionpool.py:744 - Retrying (Retry(total=2, connect=None, read=None, redirect=None, status=None)) after connection broken by 'NewConnectionError('<urllib3.connection.HTTPConnection object at 0x107606df0>: Failed to establish a new connection: [Errno 61] Connection refused')': /session/6701f7e9088bc60ab168473daa188eec/element
2021-04-14 23:18:14,028 - WARNING connectionpool.py:744 - Retrying (Retry(total=1, connect=None, read=None, redirect=None, status=None)) after connection broken by 'NewConnectionError('<urllib3.connection.HTTPConnection object at 0x107606d30>: Failed to establish a new connection: [Errno 61] Connection refused')': /session/6701f7e9088bc60ab168473daa188eec/element
2021-04-14 23:18:14,029 - WARNING connectionpool.py:744 - Retrying (Retry(total=0, connect=None, read=None, redirect=None, status=None)) after connection broken by 'NewConnectionError('<urllib3.connection.HTTPConnection object at 0x107606c40>: Failed to establish a new connection: [Errno 61] Connection refused')': /session/6701f7e9088bc60ab168473daa188eec/element
2021-04-14 23:18:14,030 - INFO fialda.py:119 - Screenshot Fialda successfully
2021-04-14 23:18:14,031 - WARNING connectionpool.py:744 - Retrying (Retry(total=2, connect=None, read=None, redirect=None, status=None)) after connection broken by 'NewConnectionError('<urllib3.connection.HTTPConnection object at 0x1076069d0>: Failed to establish a new connection: [Errno 61] Connection refused')': /session/6701f7e9088bc60ab168473daa188eec
2021-04-14 23:18:14,031 - WARNING connectionpool.py:744 - Retrying (Retry(total=1, connect=None, read=None, redirect=None, status=None)) after connection broken by 'NewConnectionError('<urllib3.connection.HTTPConnection object at 0x1076069a0>: Failed to establish a new connection: [Errno 61] Connection refused')': /session/6701f7e9088bc60ab168473daa188eec
2021-04-14 23:18:14,032 - WARNING connectionpool.py:744 - Retrying (Retry(total=0, connect=None, read=None, redirect=None, status=None)) after connection broken by 'NewConnectionError('<urllib3.connection.HTTPConnection object at 0x107606370>: Failed to establish a new connection: [Errno 61] Connection refused')': /session/6701f7e9088bc60ab168473daa188eec
2021-04-14 23:18:31,594 - INFO fialda.py:119 - Screenshot Fialda successfully
2021-04-14 23:19:35,682 - INFO fialda.py:119 - Screenshot Fialda successfully
2021-04-14 23:19:56,648 - INFO fialda.py:119 - Screenshot Fialda successfully
2021-04-14 23:25:47,607 - INFO fialda.py:119 - Screenshot Fialda successfully
2021-04-14 23:26:11,829 - INFO fialda.py:119 - Screenshot Fialda successfully
2021-04-14 23:26:13,218 - ERROR sendScreenshot.py:63 - Failed to send email Update 15 minutes at 2021-04-14 23-26  from screenshots/realtime/15_minutes/
2021-04-14 23:28:09,552 - INFO sendScreenshot.py:61 - Sent Update 15 minutes at 2021-04-14 23-28  from screenshots/realtime/15_minutes/
2021-04-14 23:30:47,229 - WARNING connectionpool.py:744 - Retrying (Retry(total=2, connect=None, read=None, redirect=None, status=None)) after connection broken by 'NewConnectionError('<urllib3.connection.HTTPConnection object at 0x109a9d070>: Failed to establish a new connection: [Errno 61] Connection refused')': /session/92c8d5f8843aa4020c9914c46da6e3aa/element
2021-04-14 23:30:47,230 - WARNING connectionpool.py:744 - Retrying (Retry(total=1, connect=None, read=None, redirect=None, status=None)) after connection broken by 'NewConnectionError('<urllib3.connection.HTTPConnection object at 0x109a9d460>: Failed to establish a new connection: [Errno 61] Connection refused')': /session/92c8d5f8843aa4020c9914c46da6e3aa/element
2021-04-14 23:30:47,231 - WARNING connectionpool.py:744 - Retrying (Retry(total=0, connect=None, read=None, redirect=None, status=None)) after connection broken by 'NewConnectionError('<urllib3.connection.HTTPConnection object at 0x109a9d5b0>: Failed to establish a new connection: [Errno 61] Connection refused')': /session/92c8d5f8843aa4020c9914c46da6e3aa/element
2021-04-14 23:30:47,233 - WARNING connectionpool.py:744 - Retrying (Retry(total=2, connect=None, read=None, redirect=None, status=None)) after connection broken by 'NewConnectionError('<urllib3.connection.HTTPConnection object at 0x109a9d850>: Failed to establish a new connection: [Errno 61] Connection refused')': /session/92c8d5f8843aa4020c9914c46da6e3aa/element
2021-04-14 23:30:47,234 - WARNING connectionpool.py:744 - Retrying (Retry(total=1, connect=None, read=None, redirect=None, status=None)) after connection broken by 'NewConnectionError('<urllib3.connection.HTTPConnection object at 0x109928f10>: Failed to establish a new connection: [Errno 61] Connection refused')': /session/92c8d5f8843aa4020c9914c46da6e3aa/element
2021-04-14 23:30:47,234 - WARNING connectionpool.py:744 - Retrying (Retry(total=0, connect=None, read=None, redirect=None, status=None)) after connection broken by 'NewConnectionError('<urllib3.connection.HTTPConnection object at 0x109928f40>: Failed to establish a new connection: [Errno 61] Connection refused')': /session/92c8d5f8843aa4020c9914c46da6e3aa/element
2021-04-14 23:30:47,236 - WARNING connectionpool.py:744 - Retrying (Retry(total=2, connect=None, read=None, redirect=None, status=None)) after connection broken by 'NewConnectionError('<urllib3.connection.HTTPConnection object at 0x109a9d6a0>: Failed to establish a new connection: [Errno 61] Connection refused')': /session/92c8d5f8843aa4020c9914c46da6e3aa/element
2021-04-14 23:30:47,236 - WARNING connectionpool.py:744 - Retrying (Retry(total=1, connect=None, read=None, redirect=None, status=None)) after connection broken by 'NewConnectionError('<urllib3.connection.HTTPConnection object at 0x109a9d370>: Failed to establish a new connection: [Errno 61] Connection refused')': /session/92c8d5f8843aa4020c9914c46da6e3aa/element
2021-04-14 23:30:47,237 - WARNING connectionpool.py:744 - Retrying (Retry(total=0, connect=None, read=None, redirect=None, status=None)) after connection broken by 'NewConnectionError('<urllib3.connection.HTTPConnection object at 0x109a9d940>: Failed to establish a new connection: [Errno 61] Connection refused')': /session/92c8d5f8843aa4020c9914c46da6e3aa/element
2021-04-14 23:30:47,240 - WARNING connectionpool.py:744 - Retrying (Retry(total=2, connect=None, read=None, redirect=None, status=None)) after connection broken by 'NewConnectionError('<urllib3.connection.HTTPConnection object at 0x109a9dc70>: Failed to establish a new connection: [Errno 61] Connection refused')': /session/92c8d5f8843aa4020c9914c46da6e3aa/element
2021-04-14 23:30:47,241 - WARNING connectionpool.py:744 - Retrying (Retry(total=1, connect=None, read=None, redirect=None, status=None)) after connection broken by 'NewConnectionError('<urllib3.connection.HTTPConnection object at 0x109a9ddf0>: Failed to establish a new connection: [Errno 61] Connection refused')': /session/92c8d5f8843aa4020c9914c46da6e3aa/element
2021-04-14 23:30:47,242 - WARNING connectionpool.py:744 - Retrying (Retry(total=0, connect=None, read=None, redirect=None, status=None)) after connection broken by 'NewConnectionError('<urllib3.connection.HTTPConnection object at 0x109a9dfa0>: Failed to establish a new connection: [Errno 61] Connection refused')': /session/92c8d5f8843aa4020c9914c46da6e3aa/element
2021-04-14 23:30:47,243 - WARNING connectionpool.py:744 - Retrying (Retry(total=2, connect=None, read=None, redirect=None, status=None)) after connection broken by 'NewConnectionError('<urllib3.connection.HTTPConnection object at 0x109af4340>: Failed to establish a new connection: [Errno 61] Connection refused')': /session/92c8d5f8843aa4020c9914c46da6e3aa/element
2021-04-14 23:30:47,244 - WARNING connectionpool.py:744 - Retrying (Retry(total=1, connect=None, read=None, redirect=None, status=None)) after connection broken by 'NewConnectionError('<urllib3.connection.HTTPConnection object at 0x109af44f0>: Failed to establish a new connection: [Errno 61] Connection refused')': /session/92c8d5f8843aa4020c9914c46da6e3aa/element
2021-04-14 23:30:47,245 - WARNING connectionpool.py:744 - Retrying (Retry(total=0, connect=None, read=None, redirect=None, status=None)) after connection broken by 'NewConnectionError('<urllib3.connection.HTTPConnection object at 0x109af46a0>: Failed to establish a new connection: [Errno 61] Connection refused')': /session/92c8d5f8843aa4020c9914c46da6e3aa/element
2021-04-14 23:30:47,246 - WARNING connectionpool.py:744 - Retrying (Retry(total=2, connect=None, read=None, redirect=None, status=None)) after connection broken by 'NewConnectionError('<urllib3.connection.HTTPConnection object at 0x109af49a0>: Failed to establish a new connection: [Errno 61] Connection refused')': /session/92c8d5f8843aa4020c9914c46da6e3aa/element
2021-04-14 23:30:47,248 - WARNING connectionpool.py:744 - Retrying (Retry(total=1, connect=None, read=None, redirect=None, status=None)) after connection broken by 'NewConnectionError('<urllib3.connection.HTTPConnection object at 0x109af4b20>: Failed to establish a new connection: [Errno 61] Connection refused')': /session/92c8d5f8843aa4020c9914c46da6e3aa/element
2021-04-14 23:30:47,249 - WARNING connectionpool.py:744 - Retrying (Retry(total=0, connect=None, read=None, redirect=None, status=None)) after connection broken by 'NewConnectionError('<urllib3.connection.HTTPConnection object at 0x109928eb0>: Failed to establish a new connection: [Errno 61] Connection refused')': /session/92c8d5f8843aa4020c9914c46da6e3aa/element
2021-04-14 23:30:47,250 - WARNING connectionpool.py:744 - Retrying (Retry(total=2, connect=None, read=None, redirect=None, status=None)) after connection broken by 'NewConnectionError('<urllib3.connection.HTTPConnection object at 0x109a9deb0>: Failed to establish a new connection: [Errno 61] Connection refused')': /session/92c8d5f8843aa4020c9914c46da6e3aa/element
2021-04-14 23:30:47,251 - WARNING connectionpool.py:744 - Retrying (Retry(total=1, connect=None, read=None, redirect=None, status=None)) after connection broken by 'NewConnectionError('<urllib3.connection.HTTPConnection object at 0x109a9ddc0>: Failed to establish a new connection: [Errno 61] Connection refused')': /session/92c8d5f8843aa4020c9914c46da6e3aa/element
2021-04-14 23:30:47,251 - WARNING connectionpool.py:744 - Retrying (Retry(total=0, connect=None, read=None, redirect=None, status=None)) after connection broken by 'NewConnectionError('<urllib3.connection.HTTPConnection object at 0x109a9d730>: Failed to establish a new connection: [Errno 61] Connection refused')': /session/92c8d5f8843aa4020c9914c46da6e3aa/element
2021-04-14 23:30:47,253 - WARNING connectionpool.py:744 - Retrying (Retry(total=2, connect=None, read=None, redirect=None, status=None)) after connection broken by 'NewConnectionError('<urllib3.connection.HTTPConnection object at 0x109a9dd60>: Failed to establish a new connection: [Errno 61] Connection refused')': /session/92c8d5f8843aa4020c9914c46da6e3aa/element
2021-04-14 23:30:47,253 - WARNING connectionpool.py:744 - Retrying (Retry(total=1, connect=None, read=None, redirect=None, status=None)) after connection broken by 'NewConnectionError('<urllib3.connection.HTTPConnection object at 0x109a9d160>: Failed to establish a new connection: [Errno 61] Connection refused')': /session/92c8d5f8843aa4020c9914c46da6e3aa/element
2021-04-14 23:30:47,254 - WARNING connectionpool.py:744 - Retrying (Retry(total=0, connect=None, read=None, redirect=None, status=None)) after connection broken by 'NewConnectionError('<urllib3.connection.HTTPConnection object at 0x109a9d670>: Failed to establish a new connection: [Errno 61] Connection refused')': /session/92c8d5f8843aa4020c9914c46da6e3aa/element
2021-04-14 23:30:47,255 - INFO fialda.py:119 - Screenshot Fialda successfully
2021-04-14 23:30:47,255 - WARNING connectionpool.py:744 - Retrying (Retry(total=2, connect=None, read=None, redirect=None, status=None)) after connection broken by 'NewConnectionError('<urllib3.connection.HTTPConnection object at 0x109a9daf0>: Failed to establish a new connection: [Errno 61] Connection refused')': /session/92c8d5f8843aa4020c9914c46da6e3aa
2021-04-14 23:30:47,256 - WARNING connectionpool.py:744 - Retrying (Retry(total=1, connect=None, read=None, redirect=None, status=None)) after connection broken by 'NewConnectionError('<urllib3.connection.HTTPConnection object at 0x109af4250>: Failed to establish a new connection: [Errno 61] Connection refused')': /session/92c8d5f8843aa4020c9914c46da6e3aa
2021-04-14 23:30:47,257 - WARNING connectionpool.py:744 - Retrying (Retry(total=0, connect=None, read=None, redirect=None, status=None)) after connection broken by 'NewConnectionError('<urllib3.connection.HTTPConnection object at 0x109af45b0>: Failed to establish a new connection: [Errno 61] Connection refused')': /session/92c8d5f8843aa4020c9914c46da6e3aa
2021-04-14 23:31:09,622 - INFO fialda.py:119 - Screenshot Fialda successfully
2021-04-14 23:31:17,253 - INFO sendScreenshot.py:61 - Sent Update 1 hour at 2021-04-14 23-31  from screenshots/realtime/1_hour/
2021-04-14 23:31:39,305 - INFO fialda.py:119 - Screenshot Fialda successfully
2021-04-14 23:31:48,592 - INFO sendScreenshot.py:61 - Sent Update 1 day at 2021-04-14 23-31  from screenshots/realtime/1_day/
